<?xml version="1.0" encoding="utf-8"?>
<!-- This URDF was automatically created by SolidWorks to URDF Exporter! Originally created by Stephen Brawner (brawner@gmail.com) 
     Commit Version: 1.6.0-4-g7f85cfe  Build Version: 1.6.7995.38578
     For more information, please see http://wiki.ros.org/sw_urdf_exporter -->
<robot
  name="badaya">
  <link
    name="base_link">
    <inertial>
      <origin
        xyz="0.000124114839491346 -0.0113416494902754 0.434727566762114"
        rpy="0 0 0" />
      <mass
        value="0.2215251621958" />
      <inertia
        ixx="0.000101897481544683"
        ixy="6.91625543372935E-08"
        ixz="-5.14067994671693E-08"
        iyy="0.000173382719946499"
        iyz="8.04509493470393E-06"
        izz="0.000158922224777981" />
    </inertial>
    <visual>
      <origin
        xyz="0 0 0"
        rpy="0 0 0" />
      <geometry>
        <mesh
          filename="package://badaya/meshes/base_link.STL" />
      </geometry>
      <material
        name="">
        <color
          rgba="0.886274509803922 0.776470588235294 0.67843137254902 1" />
      </material>
    </visual>
    <collision>
      <origin
        xyz="0 0 0"
        rpy="0 0 0" />
      <geometry>
        <mesh
          filename="package://badaya/meshes/base_link.STL" />
      </geometry>
    </collision>
  </link>
  <link
    name="waist_link">
    <inertial>
      <origin
        xyz="0.0402135117595245 -0.0022735547509958 0.0289825682297939"
        rpy="0 0 0" />
      <mass
        value="0.253025215067274" />
      <inertia
        ixx="0.000207131359721091"
        ixy="1.3383380457411E-10"
        ixz="-1.37231708481393E-07"
        iyy="6.88385602261252E-05"
        iyz="-1.27099608046946E-07"
        izz="0.000198692839118258" />
    </inertial>
    <visual>
      <origin
        xyz="0 0 0"
        rpy="0 0 0" />
      <geometry>
        <mesh
          filename="package://badaya/meshes/waist_link.STL" />
      </geometry>
      <material
        name="">
        <color
          rgba="0.996078431372549 0.870588235294118 0.76078431372549 1" />
      </material>
    </visual>
    <collision>
      <origin
        xyz="0 0 0"
        rpy="0 0 0" />
      <geometry>
        <mesh
          filename="package://badaya/meshes/waist_link.STL" />
      </geometry>
    </collision>
  </link>
  <joint
    name="waist_joint_1"
    type="revolute">
    <origin
      xyz="3.06140374162905E-05 0.0168966972091615 0.372408913427923"
      rpy="1.57077907239086 1.5707963267949 0" />
    <parent
      link="base_link" />
    <child
      link="waist_link" />
    <axis
      xyz="0 0.000978780520884311 -0.999999520994231" />
    <limit
      lower="-0.2618"
      upper="0.55850536"
      effort="3"
      velocity="3" />
  </joint>
  <link
    name="hip_link">
    <inertial>
      <origin
        xyz="0.0110096301285457 -1.07762347967555E-05 -0.0226635098061179"
        rpy="0 0 0" />
      <mass
        value="0.138823597375586" />
      <inertia
        ixx="2.38836273995558E-05"
        ixy="1.41623475234712E-08"
        ixz="-1.82744993681509E-07"
        iyy="3.83538977071312E-05"
        iyz="1.80110311566229E-10"
        izz="3.15172006085392E-05" />
    </inertial>
    <visual>
      <origin
        xyz="0 0 0"
        rpy="0 0 0" />
      <geometry>
        <mesh
          filename="package://badaya/meshes/hip_link.STL" />
      </geometry>
      <material
        name="">
        <color
          rgba="0.792156862745098 0.819607843137255 0.933333333333333 1" />
      </material>
    </visual>
    <collision>
      <origin
        xyz="0 0 0"
        rpy="0 0 0" />
      <geometry>
        <mesh
          filename="package://badaya/meshes/hip_link.STL" />
      </geometry>
    </collision>
  </link>
  <joint
    name="hip_joint_2"
    type="revolute">
    <origin
      xyz="0.05515 -1.4533E-05 0.01485"
      rpy="1.5713 -1.5708 -1.5713" />
    <parent
      link="waist_link" />
    <child
      link="hip_link" />
    <axis
      xyz="0 0 -1" />
    <limit
      lower="-0.2618"
      upper="0.5236"
      effort="3"
      velocity="3" />
  </joint>
  <link
    name="hip_right_link">
    <inertial>
      <origin
        xyz="-0.00422614947955957 1.30363239334019E-05 0.0101024474395421"
        rpy="0 0 0" />
      <mass
        value="0.00819925239367431" />
      <inertia
        ixx="1.32821149148133E-06"
        ixy="-2.10863541638775E-14"
        ixz="-1.29538092736239E-11"
        iyy="4.79909587455136E-06"
        iyz="3.91751811828721E-12"
        izz="4.48167530300692E-06" />
    </inertial>
    <visual>
      <origin
        xyz="0 0 0"
        rpy="0 0 0" />
      <geometry>
        <mesh
          filename="package://badaya/meshes/hip_right_link.STL" />
      </geometry>
      <material
        name="">
        <color
          rgba="0.792156862745098 0.819607843137255 0.933333333333333 1" />
      </material>
    </visual>
    <collision>
      <origin
        xyz="0 0 0"
        rpy="0 0 0" />
      <geometry>
        <mesh
          filename="package://badaya/meshes/hip_right_link.STL" />
      </geometry>
    </collision>
  </link>
  <joint
    name="hip_right_joint_4"
    type="revolute">
    <origin
      xyz="4.46903999165582E-05 0.0456592438827064 -0.0452"
      rpy="3.14159265358979 0 -0.000978780677142626" />
    <parent
      link="hip_link" />
    <child
      link="hip_right_link" />
    <axis
      xyz="0 0 1" />
    <limit
      lower="-0.41887902"
      upper="0.34906585"
      effort="3"
      velocity="3" />
  </joint>
  <link
    name="hip2_right_link">
    <inertial>
      <origin
        xyz="-0.0152802051528608 0.000300443248466842 -0.00231147744393315"
        rpy="0 0 0" />
      <mass
        value="0.190491121315995" />
      <inertia
        ixx="4.96584513485555E-05"
        ixy="-1.61906609668244E-07"
        ixz="1.96075652820572E-07"
        iyy="7.60017328225244E-05"
        iyz="4.25333788431949E-09"
        izz="8.03503917179731E-05" />
    </inertial>
    <visual>
      <origin
        xyz="0 0 0"
        rpy="0 0 0" />
      <geometry>
        <mesh
          filename="package://badaya/meshes/hip2_right_link.STL" />
      </geometry>
      <material
        name="">
        <color
          rgba="0.792156862745098 0.819607843137255 0.933333333333333 1" />
      </material>
    </visual>
    <collision>
      <origin
        xyz="0 0 0"
        rpy="0 0 0" />
      <geometry>
        <mesh
          filename="package://badaya/meshes/hip2_right_link.STL" />
      </geometry>
    </collision>
  </link>
  <joint
    name="hip2_right_joint_8"
    type="revolute">
    <origin
      xyz="0.0259017188345914 1.43556516252474E-05 0.031899632876882"
      rpy="0.000978780673836541 1.5707963267949 0" />
    <parent
      link="hip_right_link" />
    <child
      link="hip2_right_link" />
    <axis
      xyz="0 0.000978780517540149 0.999999520994235" />
    <limit
      lower="-0.70686"
      upper="1.4312"
      effort="10"
      velocity="3" />
  </joint>
  <link
    name="knee_right_link">
    <inertial>
      <origin
        xyz="0.0913090349122435 2.80103607640525E-05 -0.0296791212758651"
        rpy="0 0 0" />
      <mass
        value="0.0990788181729648" />
      <inertia
        ixx="2.89113990326741E-05"
        ixy="-7.6026264174878E-09"
        ixz="-1.06282733195236E-06"
        iyy="4.93830312858525E-05"
        iyz="-2.31023931628725E-09"
        izz="3.6564094559343E-05" />
    </inertial>
    <visual>
      <origin
        xyz="0 0 0"
        rpy="0 0 0" />
      <geometry>
        <mesh
          filename="package://badaya/meshes/knee_right_link.STL" />
      </geometry>
      <material
        name="">
        <color
          rgba="0.792156862745098 0.819607843137255 0.933333333333333 1" />
      </material>
    </visual>
    <collision>
      <origin
        xyz="0 0 0"
        rpy="0 0 0" />
      <geometry>
        <mesh
          filename="package://badaya/meshes/knee_right_link.STL" />
      </geometry>
    </collision>
  </link>
  <joint
    name="knee_right_joint_6"
    type="revolute">
    <origin
      xyz="0 0.029774 -0.026449"
      rpy="1.5718 0 3.1416" />
    <parent
      link="hip2_right_link" />
    <child
      link="knee_right_link" />
    <axis
      xyz="0 0 -1" />
    <limit
      lower="-1.1694"
      upper="0.29671"
      effort="10"
      velocity="3" />
  </joint>
  <link
    name="knee2_right_link">
    <inertial>
      <origin
        xyz="0.00804899987914809 -0.0336820805195894 0.0600831335075141"
        rpy="0 0 0" />
      <mass
        value="0.0193582268613659" />
      <inertia
        ixx="3.00376034908173E-05"
        ixy="-4.16144017849549E-06"
        ixz="-4.45933068227337E-20"
        iyy="1.54337706515249E-05"
        iyz="-1.37973752415303E-19"
        izz="2.14370365193726E-05" />
    </inertial>
    <visual>
      <origin
        xyz="0 0 0"
        rpy="0 0 0" />
      <geometry>
        <mesh
          filename="package://badaya/meshes/knee2_right_link.STL" />
      </geometry>
      <material
        name="">
        <color
          rgba="0.666666666666667 0.698039215686274 0.768627450980392 1" />
      </material>
    </visual>
    <collision>
      <origin
        xyz="0 0 0"
        rpy="0 0 0" />
      <geometry>
        <mesh
          filename="package://badaya/meshes/knee2_right_link.STL" />
      </geometry>
    </collision>
  </link>
  <joint
    name="knee2_right_joint_10"
    type="revolute">
    <origin
      xyz="0.112829632865214 -0.00128000102779485 0.0306185315075161"
      rpy="3.14159265358978 0 -1.57079581916587" />
    <parent
      link="knee_right_link" />
    <child
      link="knee2_right_link" />
    <axis
      xyz="0 0 -1" />
    <limit
      lower="-0.113446401"
      upper="1.500983155"
      effort="10"
      velocity="3" />
  </joint>
  <link
    name="angkle_right_link">
    <inertial>
      <origin
        xyz="-0.0037832350873081 0.0163203907687384 -0.0331964377564581"
        rpy="0 0 0" />
      <mass
        value="0.237978786468489" />
      <inertia
        ixx="0.000171283046245281"
        ixy="1.07371172497559E-06"
        ixz="-1.06118699691655E-06"
        iyy="0.000105820220556833"
        iyz="-8.74301120392093E-14"
        izz="0.000168335248057341" />
    </inertial>
    <visual>
      <origin
        xyz="0 0 0"
        rpy="0 0 0" />
      <geometry>
        <mesh
          filename="package://badaya/meshes/angkle_right_link.STL" />
      </geometry>
      <material
        name="">
        <color
          rgba="0.109803921568627 0.109803921568627 0.109803921568627 1" />
      </material>
    </visual>
    <collision>
      <origin
        xyz="0 0 0"
        rpy="0 0 0" />
      <geometry>
        <mesh
          filename="package://badaya/meshes/angkle_right_link.STL" />
      </geometry>
    </collision>
  </link>
  <joint
    name="angkle_right_joint_12"
    type="revolute">
    <origin
      xyz="-0.00128 -0.095 0.029519"
      rpy="3.1416 0 -1.5708" />
    <parent
      link="knee2_right_link" />
    <child
      link="angkle_right_link" />
    <axis
      xyz="0 0 1" />
    <limit
      lower="-0.36652"
      upper="1.85"
      effort="10"
      velocity="3" />
  </joint>
  <link
    name="foot_right_link">
    <inertial>
      <origin
        xyz="0.029264 -0.0078636 0.02291"
        rpy="0 0 0" />
      <mass
        value="0.072891" />
      <inertia
        ixx="0.00013288"
        ixy="-1.5969E-08"
        ixz="5.1443E-11"
        iyy="0.00010263"
        iyz="-3.5376E-14"
        izz="3.332E-05" />
    </inertial>
    <visual>
      <origin
        xyz="0 0 0"
        rpy="0 0 0" />
      <geometry>
        <mesh
          filename="package://badaya/meshes/foot_right_link.STL" />
      </geometry>
      <material
        name="">
        <color
          rgba="0.89804 0.91765 0.92941 1" />
      </material>
    </visual>
    <collision>
      <origin
        xyz="0 0 0"
        rpy="0 0 0" />
      <geometry>
        <mesh
          filename="package://badaya/meshes/foot_right_link.STL" />
      </geometry>
    </collision>
  </link>
  <joint
    name="foot_right_14"
    type="revolute">
    <origin
      xyz="0 0.0188 -0.0308"
      rpy="1.5708 -0.00052794 0" />
    <parent
      link="angkle_right_link" />
    <child
      link="foot_right_link" />
    <axis
      xyz="0 0 1" />
    <limit
      lower="-0.87266"
      upper="1.7453"
      effort="10"
      velocity="3" />
  </joint>
  <link
    name="hip_left_link">
    <inertial>
      <origin
        xyz="-0.00422616006071602 3.6392684704678E-06 0.0101024507687435"
        rpy="0 0 0" />
      <mass
        value="0.00819925239367435" />
      <inertia
        ixx="1.32821470046737E-06"
        ixy="-3.33735824871431E-09"
        ixz="-1.47194999802026E-11"
        iyy="4.79909257297121E-06"
        iyz="1.71482639026517E-10"
        izz="4.48167539560129E-06" />
    </inertial>
    <visual>
      <origin
        xyz="0 0 0"
        rpy="0 0 0" />
      <geometry>
        <mesh
          filename="package://badaya/meshes/hip_left_link.STL" />
      </geometry>
      <material
        name="">
        <color
          rgba="0.792156862745098 0.819607843137255 0.933333333333333 1" />
      </material>
    </visual>
    <collision>
      <origin
        xyz="0 0 0"
        rpy="0 0 0" />
      <geometry>
        <mesh
          filename="package://badaya/meshes/hip_left_link.STL" />
      </geometry>
    </collision>
  </link>
  <joint
    name="hip_left_joint_3"
    type="revolute">
    <origin
      xyz="-4.4690399917946E-05 -0.0456592438827054 -0.0452000000000022"
      rpy="3.14106471267909 0 -1.72544040170706E-05" />
    <parent
      link="hip_link" />
    <child
      link="hip_left_link" />
    <axis
      xyz="0 -0.000527940886170703 0.999999860639201" />
    <limit
      lower="-0.130899694"
      upper="0.76794"
      effort="3"
      velocity="3" />
  </joint>
  <link
    name="hip2_left_link">
    <inertial>
      <origin
        xyz="0.0152802051527435 -0.000304960239449412 0.00231049476447745"
        rpy="0 0 0" />
      <mass
        value="0.190491121319325" />
      <inertia
        ixx="4.96584513490811E-05"
        ixy="-1.61860331826737E-07"
        ixz="1.95758628097581E-07"
        iyy="7.60017328226701E-05"
        iyz="-4.25333764201523E-09"
        izz="8.03503917184427E-05" />
    </inertial>
    <visual>
      <origin
        xyz="0 0 0"
        rpy="0 0 0" />
      <geometry>
        <mesh
          filename="package://badaya/meshes/hip2_left_link.STL" />
      </geometry>
      <material
        name="">
        <color
          rgba="0.792156862745098 0.819607843137255 0.933333333333333 1" />
      </material>
    </visual>
    <collision>
      <origin
        xyz="0 0 0"
        rpy="0 0 0" />
      <geometry>
        <mesh
          filename="package://badaya/meshes/hip2_left_link.STL" />
      </geometry>
    </collision>
  </link>
  <joint
    name="hip2_left_joint_7"
    type="revolute">
    <origin
      xyz="0.0246216936494661 2.11889451403463E-05 0.0318996485089502"
      rpy="1.57077907237876 -1.57026838588464 -1.57079632678703" />
    <parent
      link="hip_left_link" />
    <child
      link="hip2_left_link" />
    <axis
      xyz="0 0.000978780525116004 -0.999999520994227" />
    <limit
      lower="-0.706858346"
      upper="0.87266"
      effort="10"
      velocity="3" />
  </joint>
  <link
    name="knee_left_link">
    <inertial>
      <origin
        xyz="0.0913090349135627 -0.0296791392209477 5.81000804317222E-06"
        rpy="0 0 0" />
      <mass
        value="0.0990788181435478" />
      <inertia
        ixx="2.89113990266018E-05"
        ixy="-1.06281617477702E-06"
        ixz="-1.19068337531037E-08"
        iyy="3.65641019569102E-05"
        iyz="-1.00154813733859E-08"
        izz="4.93830238641027E-05" />
    </inertial>
    <visual>
      <origin
        xyz="0 0 0"
        rpy="0 0 0" />
      <geometry>
        <mesh
          filename="package://badaya/meshes/knee_left_link.STL" />
      </geometry>
      <material
        name="">
        <color
          rgba="0.792156862745098 0.819607843137255 0.933333333333333 1" />
      </material>
    </visual>
    <collision>
      <origin
        xyz="0 0 0"
        rpy="0 0 0" />
      <geometry>
        <mesh
          filename="package://badaya/meshes/knee_left_link.STL" />
      </geometry>
    </collision>
  </link>
  <joint
    name="knee_left_joint_5"
    type="revolute">
    <origin
      xyz="0 -0.029826 0.026391"
      rpy="-3.1416 0 0" />
    <parent
      link="hip2_left_link" />
    <child
      link="knee_left_link" />
    <axis
      xyz="0 -1 -0.00096153" />
    <limit
      lower="-0.19199"
      upper="2.234"
      effort="10"
      velocity="3" />
  </joint>
  <link
    name="knee2_left_link">
    <inertial>
      <origin
        xyz="-0.0336820845821853 0.0106089827811614 0.0600831335075177"
        rpy="0 0 0" />
      <mass
        value="0.0193582268613658" />
      <inertia
        ixx="1.54337748764643E-05"
        ixy="-4.16144759182268E-06"
        ixz="1.83239944424891E-19"
        iyy="3.00375992658779E-05"
        iyz="-3.9605407729039E-20"
        izz="2.14370365193726E-05" />
    </inertial>
    <visual>
      <origin
        xyz="0 0 0"
        rpy="0 0 0" />
      <geometry>
        <mesh
          filename="package://badaya/meshes/knee2_left_link.STL" />
      </geometry>
      <material
        name="">
        <color
          rgba="0.666666666666667 0.698039215686274 0.768627450980392 1" />
      </material>
    </visual>
    <collision>
      <origin
        xyz="0 0 0"
        rpy="0 0 0" />
      <geometry>
        <mesh
          filename="package://badaya/meshes/knee2_left_link.STL" />
      </geometry>
    </collision>
  </link>
  <joint
    name="knee2_left_joint_9"
    type="revolute">
    <origin
      xyz="0.112829632888525 0.0306172866011919 0.00130943889737084"
      rpy="-1.57175785303239 0 -3.14159265358978" />
    <parent
      link="knee_left_link" />
    <child
      link="knee2_left_link" />
    <axis
      xyz="0 0 -1" />
    <limit
      lower="-0.785398163"
      upper="0.19199"
      effort="10"
      velocity="3" />
  </joint>
  <link
    name="angkle_left_link">
    <inertial>
      <origin
        xyz="0.0152939106906957 0.0229335658249781 -0.0307868819473238"
        rpy="0 0 0" />
      <mass
        value="0.181635293744239" />
      <inertia
        ixx="4.69097394400458E-05"
        ixy="-1.07043030324013E-06"
        ixz="1.06446704295086E-06"
        iyy="7.52709488472468E-05"
        iyz="1.07401464239873E-13"
        izz="7.47612900454884E-05" />
    </inertial>
    <visual>
      <origin
        xyz="0 0 0"
        rpy="0 0 0" />
      <geometry>
        <mesh
          filename="package://badaya/meshes/angkle_left_link.STL" />
      </geometry>
      <material
        name="">
        <color
          rgba="0.109803921568627 0.109803921568627 0.109803921568627 1" />
      </material>
    </visual>
    <collision>
      <origin
        xyz="0 0 0"
        rpy="0 0 0" />
      <geometry>
        <mesh
          filename="package://badaya/meshes/angkle_left_link.STL" />
      </geometry>
    </collision>
  </link>
  <joint
    name="angkle_left_joint_11"
    type="revolute">
    <origin
      xyz="-0.095 0.00128 0.029519"
      rpy="3.1416 0 0" />
    <parent
      link="knee2_left_link" />
    <child
      link="angkle_left_link" />
    <axis
      xyz="0 0 1" />
    <limit
      lower="-0.9163"
      upper="0.7854"
      effort="10"
      velocity="3" />
  </joint>
  <link
    name="foot_left_link">
    <inertial>
      <origin
        xyz="-0.0292721655089268 -0.00783268873028725 0.0229100000022165"
        rpy="0 0 0" />
      <mass
        value="0.0728910331402474" />
      <inertia
        ixx="0.000132875190059068"
        ixy="-1.59693308579579E-08"
        ixz="8.23948335829585E-16"
        iyy="0.00010263001002442"
        iyz="2.7123786220773E-14"
        izz="3.33197131957041E-05" />
    </inertial>
    <visual>
      <origin
        xyz="0 0 0"
        rpy="0 0 0" />
      <geometry>
        <mesh
          filename="package://badaya/meshes/foot_left_link.STL" />
      </geometry>
      <material
        name="">
        <color
          rgba="0.898039215686275 0.917647058823529 0.929411764705882 1" />
      </material>
    </visual>
    <collision>
      <origin
        xyz="0 0 0"
        rpy="0 0 0" />
      <geometry>
        <mesh
          filename="package://badaya/meshes/foot_left_link.STL" />
      </geometry>
    </collision>
  </link>
  <joint
    name="foot_left_joint_13"
    type="revolute">
    <origin
      xyz="0 0.0188 -0.0308"
      rpy="1.5708 -0.00052794 0" />
    <parent
      link="angkle_left_link" />
    <child
      link="foot_left_link" />
    <axis
      xyz="0 0 1" />
    <limit
      lower="-0.87266"
      upper="1.7104"
      effort="10"
      velocity="3" />
  </joint>
</robot>